2024-09-11 15:49:12,216 DEBUG    root            Loaded Command Group: ['gcloud', 'storage']
2024-09-11 15:49:12,288 DEBUG    root            Loaded Command Group: ['gcloud', 'storage', 'ls']
2024-09-11 15:49:12,290 DEBUG    root            Running [gcloud.storage.ls] with arguments: [PATH:1: "['gs://callisto-protocol-generator']"]
2024-09-11 15:49:12,326 DEBUG    urllib3.connectionpool Starting new HTTPS connection (1): storage.googleapis.com:443
2024-09-11 15:49:12,984 DEBUG    urllib3.connectionpool https://storage.googleapis.com:443 "GET /storage/v1/b/callisto-protocol-generator/o?alt=json&fields=prefixes%2Citems%2Fname%2Citems%2Fsize%2Citems%2Fgeneration%2CnextPageToken&delimiter=%2F&includeFoldersAsPrefixes=True&maxResults=1000&projection=noAcl HTTP/1.1" 404 247
2024-09-11 15:49:12,989 DEBUG    root            (gcloud.storage.ls) gs://callisto-protocol-generator not found: 404.
Traceback (most recent call last):
  File "/opt/homebrew/share/google-cloud-sdk/lib/googlecloudsdk/api_lib/storage/gcs_json/client.py", line 1111, in list_objects
    list_result = self.client.objects.List(
                  ^^^^^^^^^^^^^^^^^^^^^^^^^
  File "/opt/homebrew/share/google-cloud-sdk/lib/googlecloudsdk/generated_clients/apis/storage/v1/storage_v1_client.py", line 1768, in List
    return self._RunMethod(
           ^^^^^^^^^^^^^^^^
  File "/opt/homebrew/share/google-cloud-sdk/lib/third_party/apitools/base/py/base_api.py", line 737, in _RunMethod
    return self.ProcessHttpResponse(method_config, http_response, request)
           ^^^^^^^^^^^^^^^^^^^^^^^^^^^^^^^^^^^^^^^^^^^^^^^^^^^^^^^^^^^^^^^
  File "/opt/homebrew/share/google-cloud-sdk/lib/third_party/apitools/base/py/base_api.py", line 743, in ProcessHttpResponse
    self.__ProcessHttpResponse(method_config, http_response, request))
    ^^^^^^^^^^^^^^^^^^^^^^^^^^^^^^^^^^^^^^^^^^^^^^^^^^^^^^^^^^^^^^^^^
  File "/opt/homebrew/share/google-cloud-sdk/lib/third_party/apitools/base/py/base_api.py", line 609, in __ProcessHttpResponse
    raise exceptions.HttpError.FromResponse(
apitools.base.py.exceptions.HttpNotFoundError: HttpError accessing <https://storage.googleapis.com/storage/v1/b/callisto-protocol-generator/o?alt=json&fields=prefixes%2Citems%2Fname%2Citems%2Fsize%2Citems%2Fgeneration%2CnextPageToken&delimiter=%2F&includeFoldersAsPrefixes=True&maxResults=1000&projection=noAcl>: response: <{'content-type': 'application/json; charset=UTF-8', 'date': 'Wed, 11 Sep 2024 13:49:12 GMT', 'vary': 'Origin, X-Origin', 'cache-control': 'no-cache, no-store, max-age=0, must-revalidate', 'expires': 'Mon, 01 Jan 1990 00:00:00 GMT', 'pragma': 'no-cache', 'x-guploader-uploadid': 'AD-8ljvvxNbthr5YSuxb7QRKSff9nmRR_8fqWb0eQxEp-hdrEsKUADMCh2-njBbLNliusNbieCM', 'content-length': '247', 'server': 'UploadServer', 'alt-svc': 'h3=":443"; ma=2592000,h3-29=":443"; ma=2592000', 'status': 404}>, content <{
  "error": {
    "code": 404,
    "message": "The specified bucket does not exist.",
    "errors": [
      {
        "message": "The specified bucket does not exist.",
        "domain": "global",
        "reason": "notFound"
      }
    ]
  }
}
>

During handling of the above exception, another exception occurred:

Traceback (most recent call last):
  File "/opt/homebrew/share/google-cloud-sdk/lib/googlecloudsdk/calliope/cli.py", line 998, in Execute
    resources = calliope_command.Run(cli=self, args=args)
                ^^^^^^^^^^^^^^^^^^^^^^^^^^^^^^^^^^^^^^^^^
  File "/opt/homebrew/share/google-cloud-sdk/lib/googlecloudsdk/calliope/backend.py", line 838, in Run
    resources = command_instance.Run(args)
                ^^^^^^^^^^^^^^^^^^^^^^^^^^
  File "/opt/homebrew/share/google-cloud-sdk/lib/surface/storage/ls.py", line 218, in Run
    ).list_urls()
      ^^^^^^^^^^^
  File "/opt/homebrew/share/google-cloud-sdk/lib/googlecloudsdk/command_lib/storage/list_util.py", line 460, in list_urls
    self._list_url(url)
  File "/opt/homebrew/share/google-cloud-sdk/lib/googlecloudsdk/command_lib/storage/list_util.py", line 446, in _list_url
    size_in_bytes = self._print_row_list(
                    ^^^^^^^^^^^^^^^^^^^^^
  File "/opt/homebrew/share/google-cloud-sdk/lib/googlecloudsdk/command_lib/storage/list_util.py", line 356, in _print_row_list
    for i, resource_wrapper in enumerate(resource_wrappers):
  File "/opt/homebrew/share/google-cloud-sdk/lib/googlecloudsdk/command_lib/storage/list_util.py", line 292, in _recursion_helper
    for resource in iterator:
  File "/opt/homebrew/share/google-cloud-sdk/lib/googlecloudsdk/command_lib/storage/wildcard_iterator.py", line 424, in __iter__
    for resource in self._fetch_sub_bucket_resources(
  File "/opt/homebrew/share/google-cloud-sdk/lib/googlecloudsdk/command_lib/storage/wildcard_iterator.py", line 761, in _expand_object_path
    for resource in filtered_resources:
  File "/opt/homebrew/share/google-cloud-sdk/lib/googlecloudsdk/command_lib/storage/wildcard_iterator.py", line 853, in _filter_resources
    for resource in resource_iterator:
  File "/Users/wojciech.chamski@stxnext.pl/.pyenv/versions/3.11.8/lib/python3.11/heapq.py", line 375, in merge
    value = next()
            ^^^^^^
  File "/opt/homebrew/share/google-cloud-sdk/lib/googlecloudsdk/api_lib/storage/gcs_json/client.py", line 1115, in list_objects
    core_exceptions.reraise(
  File "/opt/homebrew/share/google-cloud-sdk/lib/googlecloudsdk/core/exceptions.py", line 149, in reraise
    six.reraise(type(exc_value), exc_value, tb)
  File "/opt/homebrew/share/google-cloud-sdk/lib/third_party/six/__init__.py", line 718, in reraise
    raise value.with_traceback(tb)
  File "/opt/homebrew/share/google-cloud-sdk/lib/googlecloudsdk/api_lib/storage/gcs_json/client.py", line 1111, in list_objects
    list_result = self.client.objects.List(
                  ^^^^^^^^^^^^^^^^^^^^^^^^^
  File "/opt/homebrew/share/google-cloud-sdk/lib/googlecloudsdk/generated_clients/apis/storage/v1/storage_v1_client.py", line 1768, in List
    return self._RunMethod(
           ^^^^^^^^^^^^^^^^
  File "/opt/homebrew/share/google-cloud-sdk/lib/third_party/apitools/base/py/base_api.py", line 737, in _RunMethod
    return self.ProcessHttpResponse(method_config, http_response, request)
           ^^^^^^^^^^^^^^^^^^^^^^^^^^^^^^^^^^^^^^^^^^^^^^^^^^^^^^^^^^^^^^^
  File "/opt/homebrew/share/google-cloud-sdk/lib/third_party/apitools/base/py/base_api.py", line 743, in ProcessHttpResponse
    self.__ProcessHttpResponse(method_config, http_response, request))
    ^^^^^^^^^^^^^^^^^^^^^^^^^^^^^^^^^^^^^^^^^^^^^^^^^^^^^^^^^^^^^^^^^
  File "/opt/homebrew/share/google-cloud-sdk/lib/third_party/apitools/base/py/base_api.py", line 609, in __ProcessHttpResponse
    raise exceptions.HttpError.FromResponse(
googlecloudsdk.api_lib.storage.errors.GcsNotFoundError: gs://callisto-protocol-generator not found: 404.
2024-09-11 15:49:12,997 ERROR    root            (gcloud.storage.ls) gs://callisto-protocol-generator not found: 404.
